Workbook

Sheet Start Here
B2: 📊 The Dividend Dashboard – User Instructions Welcome to The Dividend Dashboard. This tool gives a snapshot of dividend yield, portfolio diversification, and payment schedules. Please read the following before using the spreadsheet: 🧭 Tabs Overview 1. Dashboard View the live dividend yield 2. Projected Schedule Displays a heatmap of dividend payments across the year, giving a rough idea of when income is expected. 3. Portfolio Details Lists the stocks included in the dashboard. Shows current prices, yields, and sectors for each stock represented in the pie chart. ⚠️ Important Notes Do not request access – this will display your Google account info. Use the sheet as a viewer only. Do not make a copy – the paid add-on features will not function in a copied version. Instead, bookmark the original and return to check the updated yield data. 🎁 Bonus for New Users If you're new to Trading 212, click here to view the current free share promo code. It may be available even after opening your account. 🔧 Advanced Portfolio Tracking This dashboard provides a basic overview. For more detailed and customizable portfolio tracking, consider using the recommended portfolio tracker. | H2: Resources
H8: Get Free Shares on Trading 212 (even after you opened your account)
H12: Watch the Full Guide to this Pie
H15: Read The FAQ about This Pie
H19: Learn More about Investing
H23: Join the Discord Community
H27: Interest on Cash vs Dividends
H33: Get up to £100 Welcome Bonus with InvestEngine

Sheet The Dashboard
B2: The Current Yield of The Almost Daily Dividend Pie | F2: Get a Free Portfolio Tracker to see Precisely when the Dividends come in
B5: =AVERAGE('Portfolio Details'!E3:E52) -> 0.03151
B9: Total Payments throughout the Year | H9: =sum('Payment Matrix'!C3:N52) -> 256
B12: What This Means for You
B14: Example Portfolio Size | E14: Estimated Annual Dividends | I14: Monthly Average
B16: 400 | D16: ➡️ | E16: =(B5*B16) -> 12.604 | I16: =(E16/12) -> 1.0503333
B18: 1000 | D18: ➡️ | E18: =(B5*B18) -> 31.51 | I18: =(E18/12) -> 2.6258333
B20: 5000 | D20: ➡️ | E20: =(B5*B20) -> 157.55 | I20: =(E20/12) -> 13.129167
B22: 10000 | D22: ➡️ | E22: =(B5*B22) -> 315.1 | I22: =(E22/12) -> 26.258333
B24: 25000 | D24: ➡️ | E24: =(B5*B24) -> 787.75 | I24: =(E24/12) -> 65.645834
B26: 50000 | D26: ➡️ | E26: =(B5*B26) -> 1575.5 | I26: =(E26/12) -> 131.29167
B28: 100000 | D28: ➡️ | E28: =(B5*B28) -> 3151 | I28: =(E28/12) -> 262.58333
B30: 300000 | D30: ➡️ | E30: =(B5*B30) -> 9453 | I30: =(E30/12) -> 787.75

Sheet Projected Schedule
B2: Jan | C2: Feb | D2: Mar | E2: Apr | F2: May | G2: Jun | H2: Jul | I2: Aug | J2: Sep | K2: Oct | L2: Nov | M2: Dec
A3: 1 | B3: ADP | C3: BMY | D3: AFL | E3: ADP | G3: AFL | H3: ADP | I3: BMY | J3: AFL | K3: ADP | L3: BMY | M3: AFL | O3: NOTE: These are not likely to be the actual dates you get paid! Each year the payment dates varies, however this is rough estimate of when the companies will pay out. It might be that you get paid multiple dividends on the same day. It's also the case that there are delays between Trading 212 receiving the dividend and paying it to us
A4: 2 | C4: LOW | D4: GWW | E4: KO | F4: BMY | G4: GWW | H4: KO | J4: GWW | K4: KO | L4: LOW | M4: GWW
A5: 3 | B5: WMT | E5: WMT | G5: SHW | I5: LOW | L5: PNR | M5: SHW
A6: 4 | B6: KMB | C6: GD | E6: KMB | F6: LOW | H6: KMB | I6: PNR | J6: MSFT | K6: KMB | M6: KO
A7: 5 | B7: CNQ | C7: PNR | E7: CNQ | F7: PNR | H7: CNQ | I7: GD | J7: WMT | K7: CNQ | M7: MSFT
A8: 6 | D8: MSFT | F8: GD | G8: MSFT | J8: JNJ | M8: JNJ
A9: 7 | B9: PEP | C9: MA | D9: JNJ | E9: SLB | G9: JNJ | I9: MA | J9: SHW | K9: CB | L9: MA
A10: 8 | B10: CB | D10: AGNC | E10: CB | F10: MA | H10: CB | J10: EMR | M10: EMR
A11: 9 | C11: AGNC | D11: IBM | G11: AGNC | H11: ADC | I11: AGNC | J11: IBM | L11: AGNC | M11: AGNC
A12: 10 | B12: SLB | C12: AAPL | D12: CVX | F12: AGNC | G12: IBM | H12: SLB | I12: NUE | J12: PPG | L12: AAPL | M12: IBM
A13: 11 | B13: AGNC | C13: NUE | D13: EMR | F13: NUE | G13: CVX | H13: ITW | I13: AAPL | J13: CVX | K13: SLB | L13: GD
A14: 12 | B14: ITW | D14: PPG | E14: AGNC | F14: AAPL | G14: PPG | H14: AGNC | I14: ADC | J14: AGNC | K14: AGNC | L14: NUE | M14: CVX
A15: 13 | B15: MAIN | C15: ADC | D15: SHW | E15: ITW | F15: O | G15: EMR | H15: CAH | I15: PG | J15: MAIN | K15: ITW | L15: ADC | M15: PPG
A16: 14 | B16: O | C16: PG | D16: ADC | E16: MAIN | F16: MAIN | G16: ADC | H16: MAIN | I16: MAIN | J16: STAG | K16: O | L16: PG | M16: ADC
A17: 15 | B17: CAH | C17: O | D17: O | E17: O | F17: ADC | G17: O | H17: O | I17: O | J17: O | K17: MAIN | L17: O | M17: O
A18: 16 | B18: ADC | C18: MAIN | D18: MCD | E18: ADC | F18: PG | G18: MAIN | H18: ECL | I18: STAG | J18: MCD | K18: ADC | L18: MAIN | M18: MCD
A19: 17 | B19: RGLD | C19: STAG | D19: MAIN | E19: STAG | F19: STAG | G19: STAG | H19: STAG | J19: ADC | K19: RGLD | L19: STAG | M19: MAIN
A20: 18 | B20: ECL | D20: STAG | E20: CAH | G20: DUK | J20: DUK | K20: CAH | M20: STAG
A21: 19 | B21: STAG | D21: DUK | E21: ECL | H21: RGLD | K21: STAG | M21: DUK
A22: 20 | E22: RGLD | G22: MCD | K22: ECL
A23: 21 | J23: ROP
A24: 22 | D24: BLK | E24: SYY | H24: SYY | L24: C
A25: 23 | C25: C | E25: ROP | F25: C | G25: BLK | H25: ROP | I25: C | J25: BLK | M25: BLK
A26: 24 | B26: ROP | C26: RY | F26: RY | I26: RY | L26: RY
A27: 25 | B27: GOOD | C27: SBUX | E27: GOOD | F27: BMO | I27: BMO | K27: GOOD | L27: SBUX
A28: 26 | B28: CSCO | C28: GOOD | E28: CSCO | H28: CSCO | I28: SBUX | K28: CSCO
A29: 27 | B29: BNS | C29: LTC | E29: BNS | F29: SBUX | G29: GOOD | H29: BNS | J29: GOOD | K29: BNS
A30: 28 | B30: SYY | C30: BMO | D30: GOOD | E30: TD | G30: TROW | H30: GOOD | J30: TROW | K30: SYY | L30: BMO
A31: 29 | B31: JPM | C31: - | D31: TROW | E31: JPM | F31: GOOD | G31: PEP | H31: TD | J31: PEP | K31: TD | L31: GOOD | M31: TROW
A32: 30 | B32: TD | C32: - | D32: PEP | E32: LTC | F32: WMT | G32: LTC | H32: JPM | I32: GOOD | J32: LTC | K32: JPM | L32: LTC | M32: GOOD
A33: 31 | B33: LTC | C33: - | D33: LTC | E33: - | F33: LTC | G33: - | H33: LTC | I33: LTC | J33: - | K33: LTC | L33: - | M33: LTC

Sheet Portfolio Details
A2: Name | B2: Ticker | C2: Price | D2: Dividend Payment | E2: Dividend Yield | F2: Sector
A3: =YHFINANCE(B3,"Longname",FALSE) -> Apple Inc. | B3: AAPL | C3: =YHFINANCE(B3,"currentprice",FALSE) -> 270.37 | D3: =YHFINANCE(B3,"trailingAnnualDividendRate",FALSE) -> 1.02 | E3: =YHFINANCE(B3,"DividendYield",FALSE) -> 0.0038 | F3: =YHFINANCE(B3,"Sector",FALSE) -> Technology
A4: =YHFINANCE(B4,"Longname",FALSE) -> Realty Income Corporation | B4: O | C4: =YHFINANCE(B4,"currentprice",FALSE) -> 57.98 | D4: =YHFINANCE(B4,"trailingAnnualDividendRate",FALSE) -> 3.187 | E4: =YHFINANCE(B4,"DividendYield",FALSE) -> 0.0558 | F4: =YHFINANCE(B4,"Sector",FALSE) -> Real Estate
A5: =YHFINANCE(B5,"Longname",FALSE) -> Johnson & Johnson | B5: JNJ | C5: =YHFINANCE(B5,"currentprice",FALSE) -> 188.87 | D5: =YHFINANCE(B5,"trailingAnnualDividendRate",FALSE) -> 5.08 | E5: =YHFINANCE(B5,"DividendYield",FALSE) -> 0.0275 | F5: =YHFINANCE(B5,"Sector",FALSE) -> Healthcare
A6: =YHFINANCE(B6,"Longname",FALSE) -> Canadian Natural Resources Limited | B6: CNQ | C6: =YHFINANCE(B6,"currentprice",FALSE) -> 32.02 | D6: =YHFINANCE(B6,"trailingAnnualDividendRate",FALSE) -> 2.788 | E6: =YHFINANCE(B6,"DividendYield",FALSE) -> 0.052600004 | F6: =YHFINANCE(B6,"Sector",FALSE) -> Energy
A7: =YHFINANCE(B7,"Longname",FALSE) -> PepsiCo, Inc. | B7: PEP | C7: =YHFINANCE(B7,"currentprice",FALSE) -> 146.09 | D7: =YHFINANCE(B7,"trailingAnnualDividendRate",FALSE) -> 5.555 | E7: =YHFINANCE(B7,"DividendYield",FALSE) -> 0.038900003 | F7: =YHFINANCE(B7,"Sector",FALSE) -> Consumer Defensive
A8: =YHFINANCE(B8,"Longname",FALSE) -> The Procter & Gamble Company | B8: PG | C8: =YHFINANCE(B8,"currentprice",FALSE) -> 150.37 | D8: =YHFINANCE(B8,"trailingAnnualDividendRate",FALSE) -> 4.127 | E8: =YHFINANCE(B8,"DividendYield",FALSE) -> 0.028099999 | F8: =YHFINANCE(B8,"Sector",FALSE) -> Consumer Defensive
A9: =YHFINANCE(B9,"Longname",FALSE) -> LTC Properties, Inc. | B9: LTC | C9: =YHFINANCE(B9,"currentprice",FALSE) -> 35.08 | D9: =YHFINANCE(B9,"trailingAnnualDividendRate",FALSE) -> 2.28 | E9: =YHFINANCE(B9,"DividendYield",FALSE) -> 0.065 | F9: =YHFINANCE(B9,"Sector",FALSE) -> Real Estate
A10: =YHFINANCE(B10,"Longname",FALSE) -> McDonald's Corporation | B10: MCD | C10: =YHFINANCE(B10,"currentprice",FALSE) -> 298.43 | D10: =YHFINANCE(B10,"trailingAnnualDividendRate",FALSE) -> 6.98 | E10: =YHFINANCE(B10,"DividendYield",FALSE) -> 0.0249 | F10: =YHFINANCE(B10,"Sector",FALSE) -> Consumer Cyclical
A11: =YHFINANCE(B11,"Longname",FALSE) -> JPMorgan Chase & Co. | B11: JPM | C11: =YHFINANCE(B11,"currentprice",FALSE) -> 311.12 | D11: =YHFINANCE(B11,"trailingAnnualDividendRate",FALSE) -> 5.55 | E11: =YHFINANCE(B11,"DividendYield",FALSE) -> 0.019299999 | F11: =YHFINANCE(B11,"Sector",FALSE) -> Financial Services
A12: =YHFINANCE(B12,"Longname",FALSE) -> The Coca-Cola Company | B12: KO | C12: =YHFINANCE(B12,"currentprice",FALSE) -> 68.9 | D12: =YHFINANCE(B12,"trailingAnnualDividendRate",FALSE) -> 2.015 | E12: =YHFINANCE(B12,"DividendYield",FALSE) -> 0.0296 | F12: =YHFINANCE(B12,"Sector",FALSE) -> Consumer Defensive
A13: =YHFINANCE(B13,"Longname",FALSE) -> Mastercard Incorporated | B13: MA | C13: =YHFINANCE(B13,"currentprice",FALSE) -> 551.99 | D13: =YHFINANCE(B13,"trailingAnnualDividendRate",FALSE) -> 3.04 | E13: =YHFINANCE(B13,"DividendYield",FALSE) -> 0.0055 | F13: =YHFINANCE(B13,"Sector",FALSE) -> Financial Services
A14: =YHFINANCE(B14,"Longname",FALSE) -> International Business Machines Corporation | B14: IBM | C14: =YHFINANCE(B14,"currentprice",FALSE) -> 307.41 | D14: =YHFINANCE(B14,"trailingAnnualDividendRate",FALSE) -> 6.7 | E14: =YHFINANCE(B14,"DividendYield",FALSE) -> 0.0219 | F14: =YHFINANCE(B14,"Sector",FALSE) -> Technology
... A52: =YHFINANCE(B52,"Longname",FALSE) -> The Sherwin-Williams Company | B52: SHW | C52: =YHFINANCE(B52,"currentprice",FALSE) -> 344.94 | D52: =YHFINANCE(B52,"trailingAnnualDividendRate",FALSE) -> 3.085 | E52: =YHFINANCE(B52,"DividendYield",FALSE) -> 0.0092 | F52: =YHFINANCE(B52,"Sector",FALSE) -> Basic Materials
E55: Technology | F55: =COUNTIF(F3:F52, E55) -> 6
E56: Basic Materials | F56: =COUNTIF(F4:F53, E56) -> 5
E57: Real Estate | F57: =COUNTIF(F3:F54, E57) -> 6
E58: Financial Services | F58: =COUNTIF(F3:F54, E58) -> 12
E59: Consumer Defensive | F59: =COUNTIF(F3:F54, E59) -> 6
E60: Consumer Cyclical | F60: =COUNTIF(F3:F54, E60) -> 3
E61: Healthcare | F61: =COUNTIF(F3:F54, E61) -> 3
E62: Energy | F62: =COUNTIF(F3:F54, E62) -> 3
E63: Communication Services | F63: =COUNTIF(F3:F54, E63) -> 0
E64: Utilities | F64: =COUNTIF(F3:F55, E64) -> 1
E65: Industrials | F65: =COUNTIF(F3:F56, E65) -> 5

Sheet Payment Matrix
C1: January | D1: February | E1: March | F1: April | G1: May | H1: June | I1: July | J1: August | K1: September | L1: October | M1: November | N1: December
C2: =SUM(C3:C52) -> 24 | D2: =SUM(D3:D52) -> 19 | E2: =SUM(E3:E52) -> 21 | F2: =SUM(F3:F52) -> 24 | G2: =SUM(G3:G52) -> 20 | H2: =SUM(H3:H52) -> 21 | I2: =SUM(I3:I52) -> 23 | J2: =SUM(J3:J52) -> 19 | ... N2: =SUM(N3:N52) -> 21
B3: =('Portfolio Details'!B3) -> AAPL | D3: 1 | G3: 1 | J3: =(D3) -> 1 | M3: =(D3) -> 1
B4: =('Portfolio Details'!B4) -> O | C4: 1 | D4: =(C4) -> 1 | E4: =(D4) -> 1 | F4: =(E4) -> 1 | G4: =(F4) -> 1 | H4: =(G4) -> 1 | I4: =(H4) -> 1 | J4: =(I4) -> 1 | K4: =(J4) -> 1 | ... N4: =(M4) -> 1
B5: =('Portfolio Details'!B5) -> JNJ | E5: 1 | H5: =(E5) -> 1 | K5: =(E5) -> 1 | N5: =(E5) -> 1
B6: =('Portfolio Details'!B6) -> CNQ | C6: 1 | F6: =(C6) -> 1 | I6: =(C6) -> 1 | L6: =(C6) -> 1
B7: =('Portfolio Details'!B7) -> PEP | C7: 1 | E7: =(C7) -> 1 | H7: =(C7) -> 1 | K7: =(C7) -> 1
B8: =('Portfolio Details'!B8) -> PG | D8: 1 | G8: 1 | J8: 1 | M8: 1
B9: =('Portfolio Details'!B9) -> LTC | C9: 1 | D9: =(C9) -> 1 | E9: =(D9) -> 1 | F9: =(E9) -> 1 | G9: =(F9) -> 1 | H9: =(G9) -> 1 | I9: =(H9) -> 1 | J9: =(I9) -> 1 | K9: =(J9) -> 1 | ... N9: =(M9) -> 1
B10: =('Portfolio Details'!B10) -> MCD | E10: 1 | H10: =(E10) -> 1 | K10: =(E10) -> 1 | N10: =(H10) -> 1
B11: =('Portfolio Details'!B11) -> JPM | C11: 1 | F11: =(C11) -> 1 | I11: =(F11) -> 1 | L11: =(I11) -> 1
B12: =('Portfolio Details'!B12) -> KO | F12: 1 | I12: =(F12) -> 1 | L12: =(I12) -> 1 | N12: =(L12) -> 1
B13: =('Portfolio Details'!B13) -> MA | D13: 1 | G13: =(D13) -> 1 | J13: =(G13) -> 1 | M13: =(J13) -> 1
B14: =('Portfolio Details'!B14) -> IBM | E14: 1 | H14: =(E14) -> 1 | K14: =(H14) -> 1 | N14: =(K14) -> 1
B15: =('Portfolio Details'!B15) -> CAH | C15: 1 | F15: =(C15) -> 1 | I15: =(C15) -> 1 | L15: =(C15) -> 1
B16: =('Portfolio Details'!B16) -> GD | D16: 1 | G16: =(D16) -> 1 | J16: =(D16) -> 1 | M16: =(D16) -> 1
B17: =('Portfolio Details'!B17) -> RY | D17: 1 | G17: =(D17) -> 1 | J17: =(D17) -> 1 | M17: =(D17) -> 1
B18: =('Portfolio Details'!B18) -> BMO | D18: 1 | G18: =(D18) -> 1 | J18: =(D18) -> 1 | M18: =(D18) -> 1
B19: =('Portfolio Details'!B19) -> MSFT | E19: 1 | H19: =(E19) -> 1 | K19: =(H19) -> 1 | N19: =(K19) -> 1
B20: =('Portfolio Details'!B20) -> BNS | C20: 1 | F20: =(C20) -> 1 | I20: =(C20) -> 1 | L20: =(C20) -> 1
B21: =('Portfolio Details'!B21) -> CB | C21: 1 | F21: =(C21) -> 1 | I21: =(C21) -> 1 | L21: =(C21) -> 1
B22: =('Portfolio Details'!B22) -> LOW | D22: 1 | G22: =(D22) -> 1 | I22: =(C22) | J22: =(D22) -> 1 | L22: =(C22) | M22: =(D22) -> 1
B23: =('Portfolio Details'!B23) -> SYY | C23: 1 | F23: =(C23) -> 1 | I23: =(C23) -> 1 | L23: =(C23) -> 1
B24: =('Portfolio Details'!B24) -> ITW | C24: 1 | F24: =(C24) -> 1 | I24: =(C24) -> 1 | L24: =(C24) -> 1
B25: =('Portfolio Details'!B25) -> WMT | C25: 1 | F25: =(C25) -> 1 | G25: =(C25) -> 1 | K25: =(C25) -> 1
B26: =('Portfolio Details'!B26) -> KMB | C26: 1 | F26: =(C26) -> 1 | I26: =(C26) -> 1 | L26: =(C26) -> 1
B27: =('Portfolio Details'!B27) -> BLK | E27: 1 | H27: =(E27) -> 1 | K27: =(E27) -> 1 | N27: =(E27) -> 1
B28: =('Portfolio Details'!B28) -> MAIN | C28: 1 | D28: =(C28) -> 1 | E28: =(D28) -> 1 | F28: =(E28) -> 1 | G28: =(F28) -> 1 | H28: =(G28) -> 1 | I28: =(H28) -> 1 | J28: =(I28) -> 1 | K28: =(J28) -> 1 | ... N28: =(M28) -> 1
B29: =('Portfolio Details'!B29) -> ADP | C29: 1 | F29: =(C29) -> 1 | I29: =(F29) -> 1 | L29: =(F29) -> 1
B30: =('Portfolio Details'!B30) -> SBUX | D30: 1 | G30: =(D30) -> 1 | J30: =(D30) -> 1 | M30: =(D30) -> 1
B31: =('Portfolio Details'!B31) -> ECL | C31: 1 | F31: =(C31) -> 1 | I31: =(C31) -> 1 | L31: =(C31) -> 1
B32: =('Portfolio Details'!B32) -> CVX | E32: 1 | H32: =(E32) -> 1 | K32: =(H32) -> 1 | N32: =(K32) -> 1
B33: =('Portfolio Details'!B33) -> SLB | C33: 1 | F33: =(C33) -> 1 | I33: =(F33) -> 1 | L33: =(I33) -> 1
B34: =('Portfolio Details'!B34) -> DUK | E34: 1 | H34: 1 | K34: 1 | N34: 1
B35: =('Portfolio Details'!B35) -> AGNC | C35: 1 | D35: =(C35) -> 1 | E35: =(D35) -> 1 | F35: =(E35) -> 1 | G35: =(F35) -> 1 | H35: =(G35) -> 1 | I35: =(H35) -> 1 | J35: =(I35) -> 1 | K35: =(J35) -> 1 | ... N35: =(M35) -> 1
B36: =('Portfolio Details'!B36) -> STAG | C36: 1 | D36: =(C36) -> 1 | E36: =(D36) -> 1 | F36: =(E36) -> 1 | G36: =(F36) -> 1 | H36: =(G36) -> 1 | I36: =(H36) -> 1 | J36: =(I36) -> 1 | K36: =(J36) -> 1 | ... N36: =(M36) -> 1
B37: =('Portfolio Details'!B37) -> AFL | E37: 1 | H37: 1 | K37: 1 | N37: =(K37) -> 1
B38: =('Portfolio Details'!B38) -> PPG | E38: 1 | H38: =(E38) -> 1 | K38: =(H38) -> 1 | N38: =(K38) -> 1
B39: =('Portfolio Details'!B39) -> PNR | D39: 1 | G39: =(D39) -> 1 | J39: =(D39) -> 1 | M39: =(D39) -> 1
B40: =('Portfolio Details'!B40) -> NUE | D40: 1 | G40: =(D40) -> 1 | J40: =(D40) -> 1 | M40: =(D40) -> 1
...
